Crash Time: 2025-06-22 19:45:58
=
=
=
=
=
=
=
=
=
=
=
=
=
=
=
=
=
=
=
=
=
=
=
=
=
=
=
=
=
=
=
=
=
=
=
=
=
=
=
=
CRASH REPORT
=
=
=
=
=
=
=
=
=
=
=
=
=
=
=
=
=
=
=
=
=
=
=
=
=
=
=
=
=
=
=
=
=
=
=
=
=
=
=
=
Traceback (most recent call last):
  File "C:\Users\AI\OneDrive\Desktop\AI Random\GIP-GamesInProgress\Runic_Lands\systems\synapstex.py", line 1156, in render_all
    drawable.draw(screen, offset)
    ~~~~~~~~~~~~~^^^^^^^^^^^^^^^^
  File "C:\Users\AI\OneDrive\Desktop\AI Random\GIP-GamesInProgress\Runic_Lands\entities\player.py", line 188, in draw
    current_sprite = current_animation[self.current_frame] if current_animation else self.sprite_img
                     ~~~~~~~~~~~~~~~~~^^^^^^^^^^^^^^^^^^^^
IndexError: list index out of range

During handling of the above exception, another exception occurred:

Traceback (most recent call last):
  File "C:\Users\AI\OneDrive\Desktop\AI Random\GIP-GamesInProgress\Runic_Lands\main.py", line 837, in <module>
    game.run()
    ~~~~~~~~^^
  File "C:\Users\AI\OneDrive\Desktop\AI Random\GIP-GamesInProgress\Runic_Lands\main.py", line 345, in run
    self.draw()
    ~~~~~~~~~^^
  File "C:\Users\AI\OneDrive\Desktop\AI Random\GIP-GamesInProgress\Runic_Lands\main.py", line 308, in draw
    self.graphics.render_all(self.screen)
    ~~~~~~~~~~~~~~~~~~~~~~~~^^^^^^^^^^^^^
  File "C:\Users\AI\OneDrive\Desktop\AI Random\GIP-GamesInProgress\Runic_Lands\systems\synapstex.py", line 1166, in render_all
    print(f"Error drawing {type(drawable)}: {e}", exc_info=True)
    ~~~~~^^^^^^^^^^^^^^^^^^^^^^^^^^^^^^^^^^^^^^^^^^^^^^^^^^^^^^^
TypeError: print() got an unexpected keyword argument 'exc_info'
